Workbook

Sheet Petunjuk
A1: ITAM - Workbook Testing
A2: Workbook khusus skenario testing/UAT semua modul. Mulai dari sheet Ringkasan untuk coverage, lalu gunakan sheet Alur_Per_Role untuk membaca alur user per role, dan buka Semua_Skenario atau sheet modul untuk eksekusi test case detail.
A4: Tujuan | B4: Menjadi master workbook skenario testing semua modul. | D4: Ringkasan Cepat
A5: Struktur Workbook | B5: 1) Ringkasan = coverage modul dan status. 2) Alur_Per_Role = siapa login, masuk ke modul mana, lalu ngapain. 3) Matriks_Role_Modul = akses role vs modul. 4) Semua_Skenario + sheet modul = eksekusi test detail. | D5: Total Skenario | E5: =COUNTIF(Semua_Skenario!$A:$A,"<>")-3 -> 243
A6: Cara Pakai Disarankan | B6: Pahami dahulu alur user di Alur_Per_Role, lalu tandai skenario detail di sheet modul. Ini membuat workbook lebih mudah dipahami untuk UAT, demo, dan diskusi fitur. | D6: High Priority | E6: =COUNTIF(Semua_Skenario!$H:$H,"High") -> 144
A7: Istilah | B7: Istilah modul, fitur, dan role disesuaikan dengan kode, UI, dan dokumen repo ITAM yang ada saat ini. | D7: Medium Priority | E7: =COUNTIF(Semua_Skenario!$H:$H,"Medium") -> 94
A8: Sumber Utama | B8: Repo GitHub ITAM + dokumen diagram per modul, panduan penggunaan lengkap, matriks akses role, dan alur end-to-end. | D8: Pass | E8: =COUNTIF(Semua_Skenario!$M:$M,"Pass") -> 0
A9: Status Eksekusi | B9: Gunakan Not Started, In Progress, Pass, Fail, atau Blocked. | D9: Fail | E9: =COUNTIF(Semua_Skenario!$M:$M,"Fail") -> 0
A10: Catatan | B10: Kolom Actual Result dan Catatan dipakai untuk hasil UAT nyata. Jangan ubah kolom referensi jika ingin jejak sumber tetap rapi. | D10: Blocked | E10: =COUNTIF(Semua_Skenario!$M:$M,"Blocked") -> 0

Sheet Referensi
A1: Not Started | B1: High | C1: Positive
A2: In Progress | B2: Medium | C2: Negative
A3: Pass | B3: Low | C3: Authorization
A4: Fail | C4: Integration
A5: Blocked
A6: N/A

Sheet Semua_Skenario
A1: Master Semua Skenario
A2: Gunakan sheet Alur_Per_Role untuk membaca flow user per role sebelum mengeksekusi test case detail di sheet ini.
A4: ID Skenario | B4: Kelompok Area | C4: Modul | D4: Fitur | E4: Tujuan Uji | F4: Jenis Uji | G4: Role Uji | H4: Prioritas | I4: Precondition | J4: Langkah Uji | K4: Hasil yang Diharapkan | L4: Data Uji | M4: Status Eksekusi | N4: Actual Result | O4: Catatan | P4: Sumber Acuan
A5: AUTH-001 | B5: Fondasi | C5: Auth and Dashboard | D5: Login | E5: Memastikan user dapat login dengan kredensial tenant yang valid. | F5: Positive | G5: Public | H5: High | I5: Tenant aktif; akun aktif; captcha dapat digunakan. | J5: 1. Buka halaman login. 2. Isi Tenant Code, Email Address, Password, dan captcha token. 3. Klik Sign In / Login. 4. Tunggu redirect ke home. | K5: - Session cookie terbentuk. - User diarahkan ke dashboard. - Data /auth/me berhasil dibaca dan shell aplikasi tampil. | L5: tenant code valid; email valid; password valid | M5: Not Started | N5: V | P5: https://raw.githubusercontent.com/MuhamadRamdhani/ITAM/main/docs/panduan-penggunaan-lengkap.md
A6: AUTH-002 | B6: Fondasi | C6: Auth and Dashboard | D6: Login | E6: Memastikan login ditolak saat password salah. | F6: Negative | G6: Public | H6: High | I6: Tenant aktif; akun ada. | J6: 1. Buka halaman login. 2. Isi Tenant Code dan Email valid, tetapi Password salah. 3. Selesaikan captcha. 4. Submit form login. | K6: - Login ditolak. - Pesan error tampil. - Tidak ada redirect ke dashboard dan sesi tidak dibuat. | L6: password invalid | M6: Not Started | N6: V | P6: https://raw.githubusercontent.com/MuhamadRamdhani/ITAM/main/docs/panduan-penggunaan-lengkap.md
A7: AUTH-003 | B7: Fondasi | C7: Auth and Dashboard | D7: Login | E7: Memastikan tenant dengan contract expired / suspended diblokir. | F7: Negative | G7: Public | H7: High | I7: Siapkan tenant expired atau suspended. | J7: 1. Buka halaman login. 2. Masukkan kredensial akun tenant expired atau suspended. 3. Selesaikan captcha dan submit. | K7: - Login ditolak. - Modal/penjelasan terkait contract atau suspension tampil. - User tetap berada di login page. | L7: tenant contract expired / tenant suspended | M7: Not Started | N7: V | P7: https://raw.githubusercontent.com/MuhamadRamdhani/ITAM/main/docs/panduan-penggunaan-lengkap.md
A8: AUTH-004 | B8: Fondasi | C8: Auth and Dashboard | D8: Refresh Session | E8: Memastikan access token yang expired dapat dipulihkan otomatis dengan refresh. | F8: Integration | G8: All authenticated users | H8: High | I8: User sudah login; refresh token masih valid. | J8: 1. Biarkan access token expired atau simulasi request protected saat token access sudah tidak valid. 2. Akses halaman protected. 3. Amati request refresh dan retry request asal. | K8: - Client memanggil /auth/refresh. - Request protected diulang otomatis. - User tetap berada di halaman aplikasi tanpa login ulang. | M8: Not Started | N8: V | O8: Sangat penting untuk regression auth wrapper. | P8: https://raw.githubusercontent.com/MuhamadRamdhani/ITAM/main/docs/alur-end-to-end-login-sampai-kpi-dan-internal-audit.md
A9: AUTH-005 | B9: Fondasi | C9: Auth and Dashboard | D9: Logout | E9: Memastikan logout mengakhiri sesi dengan aman. | F9: Positive | G9: All authenticated users | H9: High | I9: User sudah login. | J9: 1. Buka application shell. 2. Klik logout. 3. Tunggu redirect ke login. 4. Coba buka halaman protected kembali. | K9: - User kembali ke login. - Halaman protected tidak bisa diakses tanpa login ulang. - Sesi lama tidak dapat dipakai lagi. | M9: Not Started | N9: V | P9: https://raw.githubusercontent.com/MuhamadRamdhani/ITAM/main/docs/generate-itam-test-scenarios.ps1
A10: AUTH-006 | B10: Fondasi | C10: Auth and Dashboard | D10: Dashboard | E10: Memastikan dashboard menampilkan summary cards dan quick links. | F10: Positive | G10: All authenticated users | H10: High | I10: User sudah login. | J10: 1. Buka home/dashboard. 2. Periksa summary cards. 3. Periksa quick links utama. 4. Klik satu quick link. | K10: - Summary cards tampil. - Quick links ke create asset/document/upload evidence terlihat sesuai peran. - Navigasi quick link berjalan. | M10: Not Started | N10: V | P10: https://raw.githubusercontent.com/MuhamadRamdhani/ITAM/main/docs/panduan-penggunaan-lengkap.md
A11: AUTH-007 | B11: Fondasi | C11: Auth and Dashboard | D11: Dashboard Visibility | E11: Memastikan launcher mengikuti role user. | F11: Authorization | G11: SUPERADMIN/TENANT_ADMIN/ITAM_MANAGER/AUDITOR | H11: High | I11: Siapkan beberapa akun dengan role berbeda. | J11: 1. Login sebagai role pertama dan catat launcher yang muncul. 2. Logout lalu login sebagai role kedua. 3. Bandingkan launcher dan tombol aksi yang terlihat. | K11: - Launcher mengikuti role. - Modul yang tidak relevan tidak ditampilkan. - Tidak ada tombol aksi write untuk role read-only. | M11: Not Started | N11: V | P11: https://raw.githubusercontent.com/MuhamadRamdhani/ITAM/main/docs/matriks-akses-role.md
A12: AUTH-008 | B12: Fondasi | C12: Auth and Dashboard | D12: Login | E12: Memastikan login ditolak bila captcha belum diisi atau token captcha invalid/expired. | F12: Negative | G12: Public | H12: High | I12: Tenant aktif; akun aktif; site key captcha tersedia. | J12: 1. Buka halaman login. 2. Isi Tenant Code, Email Address, dan Password valid. 3. Jangan selesaikan captcha atau gunakan token captcha invalid. 4. Klik login. | K12: - Login ditolak. - Pesan captcha tampil. - Widget captcha di-reset bila token invalid/expired. | L12: captcha kosong / captcha invalid | M12: Not Started | N12: V | P12: https://raw.githubusercontent.com/MuhamadRamdhani/ITAM/main/apps/web/app/login/page.tsx
A13: AUTH-009 | B13: Fondasi | C13: Auth and Dashboard | D13: Login | E13: Memastikan login diblokir untuk tenant dengan contract not set / not active / suspended. | F13: Negative | G13: Public | H13: High | I13: Siapkan tenant pada beberapa status kontrak: not set, expired, suspended. | J13: 1. Login menggunakan akun tenant yang kontraknya bermasalah. 2. Selesaikan captcha. 3. Submit form. | K13: - Login ditolak. - Modal status tenant/kontrak tampil sesuai kondisi. - Tidak ada redirect ke dashboard. | L13: tenant contract not set / not active / suspended | M13: Not Started | N13: V | P13: https://raw.githubusercontent.com/MuhamadRamdhani/ITAM/main/apps/web/app/login/page.tsx
A14: AUTH-010 | B14: Fondasi | C14: Auth and Dashboard | D14: Login | E14: Memastikan proteksi double submit bekerja pada tombol login. | F14: Authorization | G14: Public | H14: Medium | I14: Halaman login terbuka. | J14: 1. Isi semua field valid. 2. Klik tombol login berkali-kali dengan cepat. 3. Amati request yang dikirim. | K14: - Hanya satu proses login yang aktif. - Tombol/indikator submit mencegah duplicate request. - Tidak muncul sesi ganda atau error balapan request. | L14: rapid click login | M14: Not Started | N14: V | P14: https://raw.githubusercontent.com/MuhamadRamdhani/ITAM/main/apps/web/app/login/page.tsx
A15: AUTH-011 | B15: Fondasi | C15: Auth and Dashboard | D15: Refresh Session | E15: Memastikan ketika refresh token tidak valid, user diarahkan kembali ke login dengan event session-expired. | F15: Integration | G15: All authenticated users | H15: High | I15: User pernah login; access token dan refresh token sudah invalid atau refresh endpoint gagal. | J15: 1. Akses halaman protected saat sesi sudah tidak bisa dipulihkan. 2. Amati respons client setelah refresh gagal. | K15: - Event session-expired dipicu. - Guard menampilkan pesan sesi habis. - User diarahkan ke halaman login. | L15: session expired total | M15: Not Started | N15: V | P15: https://raw.githubusercontent.com/MuhamadRamdhani/ITAM/main/apps/web/app/lib/api.ts
A16: AUTH-012 | B16: Fondasi | C16: Auth and Dashboard | D16: Logout | E16: Memastikan logout menghapus sesi dan user tidak lagi bisa mengakses halaman protected. | F16: Positive | G16: All authenticated users | H16: High | I16: User sudah login ke aplikasi. | J16: 1. Klik tombol Logout. 2. Konfirmasi bila ada. 3. Coba akses kembali halaman protected dari tab yang sama atau refresh browser. | K16: - Session cookie dibersihkan. - User kembali ke login. - Halaman protected meminta login lagi. | M16: Not Started | N16: V | P16: https://raw.githubusercontent.com/MuhamadRamdhani/ITAM/main/docs/alur-end-to-end-login-sampai-kpi-dan-internal-audit.md
A17: DASH-001 | B17: Fondasi | C17: Auth and Dashboard | D17: Dashboard Summary | E17: Memastikan summary cards termuat setelah login dan menampilkan kondisi inti tenant. | F17: Positive | G17: All authenticated users | H17: High | I17: User login valid dan memiliki akses ke home/dashboard. | J17: 1. Login ke aplikasi. 2. Tunggu dashboard selesai dimuat. 3. Periksa summary cards. | K17: - Ringkasan seperti total assets, pending approvals, documents in review, evidence, scope, atau governance termuat. - Tidak ada error load pada komponen utama dashboard. | M17: Not Started | N17: V | P17: https://raw.githubusercontent.com/MuhamadRamdhani/ITAM/main/apps/web/app/components/DashboardSummaryCards.tsx
A18: DASH-002 | B18: Fondasi | C18: Auth and Dashboard | D18: Vendor Contract Alert | E18: Memastikan vendor contract alert tampil ketika ada kontrak expiring atau expired. | F18: Positive | G18: All authenticated users | H18: Medium | I18: Tersedia data kontrak dengan health EXPIRING atau EXPIRED. | J18: 1. Buka dashboard. 2. Cari kartu Vendor Contract Alert. 3. Klik tautan ke modul Contracts bila tersedia. | K18: - Jumlah expiring/expired tampil benar. - Link mengarah ke Contracts dengan konteks yang relevan. | L18: contracts health expiring/expired | M18: Not Started | N18: V | P18: https://raw.githubusercontent.com/MuhamadRamdhani/ITAM/main/apps/web/app/components/DashboardSummaryCards.tsx
A19: DASH-003 | B19: Fondasi | C19: Auth and Dashboard | D19: Launcher Visibility | E19: Memastikan launcher/dashboard menu hanya menampilkan modul yang relevan untuk role yang login. | F19: Authorization | G19: SUPERADMIN/TENANT_ADMIN/ITAM_MANAGER/ASSET_CUSTODIAN/AUDITOR | H19: High | I19: Siapkan akun dengan role berbeda. | J19: 1. Login dengan role A, catat launcher yang muncul. 2. Logout. 3. Login dengan role B/C/D. 4. Bandingkan launcher yang tampil. | K19: - Modul yang ditampilkan sesuai role matrix. - Role read-only tidak melihat aksi operasional yang tidak berwenang. | L19: multi-role accounts | M19: Not Started | N19: V | P19: https://raw.githubusercontent.com/MuhamadRamdhani/ITAM/main/docs/matriks-akses-role.md
A20: DASH-004 | B20: Fondasi | C20: Auth and Dashboard | D20: Quick Links | E20: Memastikan quick links di dashboard mengarah ke halaman target yang benar. | F20: Positive | G20: All authenticated users | H20: Medium | I20: Dashboard sudah terbuka. | J20: 1. Klik beberapa quick links seperti New Asset, New Document, Upload Evidence, Vendors, Contracts, atau Pending Approvals. 2. Verifikasi halaman tujuan. | K20: - Navigasi berhasil tanpa 404/500. - Halaman target sesuai label quick link. - Role yang tidak berwenang tidak bisa melewati proteksi backend/UI. | M20: Not Started | N20: V | P20: https://raw.githubusercontent.com/MuhamadRamdhani/ITAM/main/apps/web/app/page.tsx
A21: DASH-005 | B21: Fondasi | C21: Auth and Dashboard | D21: Dashboard Unauthorized Handling | E21: Memastikan dashboard menangani unauthorized dengan benar ketika sesi hilang saat sedang berada di aplikasi. | F21: Integration | G21: All authenticated users | H21: High | I21: User sempat login lalu sesi dihapus/expired. | J21: 1. Buka dashboard. 2. Hapus cookie sesi atau tunggu sesi habis. 3. Refresh halaman atau trigger API dashboard. | K21: - Dashboard menampilkan handling session missing/expired. - Client mencoba refresh bila memungkinkan. - Jika gagal, user kembali ke login dengan aman. | M21: Not Started | N21: V | P21: https://raw.githubusercontent.com/MuhamadRamdhani/ITAM/main/apps/web/app/components/DashboardSummaryCards.tsx
A22: ASSET-001 | B22: Core ITAM | C22: Assets | D22: Assets List | E22: Memastikan list asset dapat dicari dan difilter. | F22: Positive | G22: Tenant-scoped | H22: High | I22: Data asset minimal 5 record dengan type/state berbeda tersedia. | J22: 1. Buka halaman Assets. 2. Gunakan search berdasarkan asset tag atau name. 3. Pilih Asset Type dan Lifecycle State. 4. Terapkan filter. | K22: - Daftar asset menyesuaikan filter. - Page size dan pagination tetap konsisten. - Filter mengambil nilai dari config tenant. | M22: Not Started | N22: V | P22: https://raw.githubusercontent.com/MuhamadRamdhani/ITAM/main/docs/panduan-penggunaan-lengkap.md
A23: ASSET-002 | B23: Core ITAM | C23: Assets | D23: New Asset | E23: Memastikan asset baru dapat dibuat oleh role yang diizinkan. | F23: Positive | G23: TENANT_ADMIN/ITAM_MANAGER | H23: High | I23: Master asset type dan lifecycle state sudah tersedia. | J23: 1. Buka Assets > New Asset. 2. Isi Asset Tag, Name, Asset Type, Initial State, Status, dan coverage dates yang relevan. 3. Simpan data. | K23: - Asset baru tersimpan. - User diarahkan ke asset detail atau asset terlihat di list. - Nilai asset type dan state sesuai pilihan. | M23: Not Started | N23: V | P23: https://raw.githubusercontent.com/MuhamadRamdhani/ITAM/main/docs/panduan-penggunaan-lengkap.md
A24: ASSET-003 | B24: Core ITAM | C24: Assets | D24: New Asset | E24: Memastikan role non-operasional tidak dapat membuat asset. | F24: Authorization | G24: AUDITOR | H24: High | I24: Login sebagai role read-only. | J24: 1. Buka halaman Assets. 2. Coba akses tombol New Asset atau route create asset. 3. Coba submit form bila route berhasil dibuka. | K24: - Tombol create tidak tampil atau akses backend ditolak. - Tidak ada asset baru yang tersimpan. | M24: Not Started | N24: V | P24: https://raw.githubusercontent.com/MuhamadRamdhani/ITAM/main/docs/matriks-akses-role.md
A25: ASSET-004 | B25: Core ITAM | C25: Assets | D25: Ownership Panel | E25: Memastikan owner/custodian/location dapat diubah dan history tetap terjaga. | F25: Positive | G25: TENANT_ADMIN/ITAM_MANAGER/ASSET_CUSTODIAN | H25: High | I25: Asset sudah ada; department, identity, dan location master tersedia. | J25: 1. Buka asset detail. 2. Masuk ke Ownership Panel. 3. Cari dan pilih department, identity, dan location baru. 4. Simpan perubahan. | K25: - Ownership aktif berubah. - History ownership bertambah. - Lookup mengambil data dari master tenant. | M25: Not Started | N25: V | P25: https://raw.githubusercontent.com/MuhamadRamdhani/ITAM/main/docs/panduan-penggunaan-lengkap.md
A26: ASSET-005 | B26: Core ITAM | C26: Assets | D26: Lifecycle Panel | E26: Memastikan lifecycle transition biasa dapat dijalankan saat gate terpenuhi. | F26: Positive | G26: Role operasional | H26: High | I26: Asset memiliki transition yang tidak membutuhkan approval. | J26: 1. Buka asset detail. 2. Masuk ke Lifecycle Panel. 3. Pilih Target State yang valid. 4. Submit transition. | K26: - Current state berubah. - History state bertambah. - Tidak ada approval record baru bila transition tidak mensyaratkan approval. | M26: Not Started | N26: V | P26: https://raw.githubusercontent.com/MuhamadRamdhani/ITAM/main/docs/panduan-penggunaan-lengkap.md
A27: ASSET-006 | B27: Core ITAM | C27: Assets | D27: Lifecycle Panel | E27: Memastikan transition yang membutuhkan approval membuat approval record. | F27: Integration | G27: Role operasional | H27: High | I27: Asset memiliki transition dengan indikator approval required. | J27: 1. Buka asset detail. 2. Pilih transition yang membutuhkan approval. 3. Submit action. 4. Buka modul Approvals dan cari record yang dibuat. | K27: - Approval record baru muncul. - State final asset belum berubah sampai approval disetujui. - Audit trail workflow bertambah. | M27: Not Started | N27: V | P27: https://raw.githubusercontent.com/MuhamadRamdhani/ITAM/main/docs/panduan-penggunaan-lengkap.md
A28: ASSET-007 | B28: Core ITAM | C28: Assets | D28: Software Panels | E28: Memastikan software installation dan assignment dapat dikelola dari asset detail. | F28: Integration | G28: SUPERADMIN/TENANT_ADMIN/ITAM_MANAGER | H28: Medium | I28: Software product aktif tersedia; identity tenant tersedia. | J28: 1. Buka asset detail. 2. Tambahkan software installation. 3. Tambahkan assignment ke identity. 4. Refresh panel. | K28: - Installation tersimpan. - Assignment tersimpan. - History installation/assignment dapat dilihat ulang. | M28: Not Started | N28: V | P28: https://raw.githubusercontent.com/MuhamadRamdhani/ITAM/main/docs/panduan-penggunaan-lengkap.md
A29: ASSET-008 | B29: Core ITAM | C29: Assets | D29: Transfer Action | E29: Memastikan action transfer hanya muncul untuk role tertentu. | F29: Authorization | G29: SUPERADMIN/TENANT_ADMIN/ITAM_MANAGER vs AUDITOR | H29: Medium | I29: Siapkan akun role operasional dan role read-only. | J29: 1. Login sebagai role operasional dan buka Assets. 2. Catat apakah action Transfer tampil. 3. Login sebagai role read-only dan ulangi pemeriksaan. | K29: - Action Transfer hanya tersedia untuk role yang diizinkan. - Role read-only tidak melihat atau tidak dapat menjalankan transfer. | M29: Not Started | N29: V | P29: https://raw.githubusercontent.com/MuhamadRamdhani/ITAM/main/docs/alur-end-to-end-login-sampai-kpi-dan-internal-audit.md
A30: ASSET-009 | B30: Core ITAM | C30: Assets | D30: Assets List | E30: Memastikan halaman Assets melakukan bootstrap auth dan config tenant dengan benar sebelum memuat list. | F30: Integration | G30: Tenant-scoped | H30: High | I30: User login; config asset types, lifecycle states, dan config UI tersedia. | J30: 1. Buka halaman Assets. 2. Amati load awal halaman. 3. Pastikan user profile, config UI, asset types, lifecycle states, dan list asset termuat. | K30: - Halaman tidak blank/crash. - Dropdown filter terisi dari config tenant. - List asset muncul setelah bootstrap selesai. | M30: Not Started | N30: V | P30: https://raw.githubusercontent.com/MuhamadRamdhani/ITAM/main/apps/web/app/assets/AssetsClient.tsx
A31: ASSET-010 | B31: Core ITAM | C31: Assets | D31: Assets List | E31: Memastikan invalid page size ditolak sesuai config server. | F31: Negative | G31: Tenant-scoped | H31: High | I31: Assets page dapat diakses. | J31: 1. Manipulasi URL page_size ke nilai yang tidak ada pada config. 2. Reload halaman Assets. | K31: - Pesan invalid page size muncul atau request ditolak. - Halaman tidak menampilkan data dengan page size liar. - Enforcement mengikuti config server. | L31: page_size di luar config | M31: Not Started | N31: V | P31: https://raw.githubusercontent.com/MuhamadRamdhani/ITAM/main/apps/web/app/assets/AssetsClient.tsx
A32: ASSET-011 | B32: Core ITAM | C32: Assets | D32: Assets List | E32: Memastikan empty state tampil saat hasil pencarian tidak ditemukan. | F32: Negative | G32: Tenant-scoped | H32: Medium | I32: Assets page dapat diakses. | J32: 1. Cari asset dengan kata kunci yang pasti tidak ada. 2. Submit filter/search. | K32: - Tabel/list tidak error. - UI menampilkan informasi bahwa tidak ada asset yang cocok. - Filter tetap dapat diubah kembali. | L32: keyword tidak ada | M32: Not Started | N32: V | P32: https://raw.githubusercontent.com/MuhamadRamdhani/ITAM/main/apps/web/app/assets/AssetsClient.tsx
A33: ASSET-012 | B33: Core ITAM | C33: Assets | D33: New Asset | E33: Memastikan coverage field mengikuti tipe asset kategori hardware/network. | F33: Positive | G33: TENANT_ADMIN/ITAM_MANAGER | H33: Medium | I33: Form New Asset terbuka. | J33: 1. Pilih Asset Type HARDWARE atau NETWORK. 2. Amati field coverage yang muncul. 3. Isi warranty/support dates bila tersedia. | K33: - Coverage field menonjolkan warranty/support. - Field subscription tidak menjadi fokus utama untuk mode hardware. - User tidak bingung karena field selaras dengan jenis asset. | L33: asset type HARDWARE / NETWORK | M33: Not Started | N33: V | P33: https://raw.githubusercontent.com/MuhamadRamdhani/ITAM/main/apps/web/app/assets/new/page.tsx
A34: ASSET-013 | B34: Core ITAM | C34: Assets | D34: New Asset | E34: Memastikan coverage field mengikuti tipe asset kategori software/saas/cloud/vm_container. | F34: Positive | G34: TENANT_ADMIN/ITAM_MANAGER | H34: Medium | I34: Form New Asset terbuka. | J34: 1. Pilih Asset Type SOFTWARE, SAAS, CLOUD, atau VM_CONTAINER. 2. Amati perubahan field coverage. 3. Isi subscription dates yang relevan. | K34: - Coverage field menonjolkan subscription/license term. - Tampilan form menyesuaikan jenis asset yang dipilih. | L34: asset type SOFTWARE / SAAS / CLOUD / VM_CONTAINER | M34: Not Started | N34: V | P34: https://raw.githubusercontent.com/MuhamadRamdhani/ITAM/main/apps/web/app/assets/new/page.tsx
A35: ASSET-014 | B35: Core ITAM | C35: Assets | D35: New Asset | E35: Memastikan validasi field wajib berjalan saat create asset. | F35: Negative | G35: TENANT_ADMIN/ITAM_MANAGER | H35: High | I35: Form New Asset terbuka. | J35: 1. Biarkan Asset Tag atau Name kosong. 2. Atau kosongkan Asset Type / Initial State. 3. Klik simpan. | K35: - Form menolak submit. - Pesan validasi tampil. - Tidak ada asset baru yang tersimpan. | L35: field wajib kosong | M35: Not Started | N35: V | P35: https://raw.githubusercontent.com/MuhamadRamdhani/ITAM/main/docs/panduan-penggunaan-lengkap.md
A36: ASSET-015 | B36: Core ITAM | C36: Assets | D36: Asset Detail | E36: Memastikan asset detail dapat dibuka dari list dan berfungsi sebagai hub modul lanjutan. | F36: Positive | G36: Tenant-scoped | H36: High | I36: Ada minimal satu asset pada list. | J36: 1. Dari Assets List klik View/Detail. 2. Tunggu halaman Asset Detail terbuka. 3. Tinjau panel utama yang tersedia. | K36: - Asset Detail terbuka. - Ownership, Lifecycle, Software Installations, dan Software Assignments dapat diakses sesuai role. - Tidak ada mismatch asset ID. | M36: Not Started | N36: V | P36: https://raw.githubusercontent.com/MuhamadRamdhani/ITAM/main/docs/diagram-per-modul.md
A37: ASSET-016 | B37: Core ITAM | C37: Assets | D37: Ownership Panel | E37: Memastikan role read-only seperti AUDITOR tidak dapat mengubah ownership. | F37: Authorization | G37: AUDITOR | H37: High | I37: Login sebagai AUDITOR; asset tersedia. | J37: 1. Buka Asset Detail. 2. Akses Ownership Panel. 3. Coba ubah department/custodian/location lalu simpan. | K37: - Aksi ubah tidak tersedia atau ditolak. - Tidak ada perubahan ownership yang tersimpan. | M37: Not Started | N37: V | P37: https://raw.githubusercontent.com/MuhamadRamdhani/ITAM/main/docs/matriks-akses-role.md
A38: ASSET-017 | B38: Core ITAM | C38: Assets | D38: Lifecycle Panel | E38: Memastikan current state, transition options, dan history lifecycle tampil pada asset detail. | F38: Positive | G38: Tenant-scoped | H38: High | I38: Asset sudah ada dan memiliki state aktif. | J38: 1. Buka Asset Detail. 2. Masuk ke Lifecycle Panel. 3. Periksa current state, target state, dan history. | K38: - Current state terlihat jelas. - Opsi transition yang valid ditampilkan. - History lifecycle tersedia untuk audit trail. | M38: Not Started | N38: V | P38: https://raw.githubusercontent.com/MuhamadRamdhani/ITAM/main/docs/panduan-penggunaan-lengkap.md
A39: ASSET-018 | B39: Core ITAM | C39: Assets | D39: Lifecycle Panel | E39: Memastikan transition yang tidak membutuhkan approval mengubah state langsung. | F39: Integration | G39: TENANT_ADMIN/ITAM_MANAGER | H39: High | I39: Siapkan asset dengan transition direct yang valid. | J39: 1. Buka Lifecycle Panel. 2. Pilih target state direct. 3. Submit transition. | K39: - State asset berubah langsung. - History bertambah. - Tidak ada pending approval yang tersisa untuk transition ini. | L39: transition direct | M39: Not Started | N39: V | P39: https://raw.githubusercontent.com/MuhamadRamdhani/ITAM/main/docs/diagram-per-modul.md
A40: ASSET-019 | B40: Core ITAM | C40: Assets | D40: Lifecycle Panel | E40: Memastikan transition yang membutuhkan approval membuat record approval sebelum state final berubah. | F40: Integration | G40: TENANT_ADMIN/ITAM_MANAGER | H40: High | I40: Siapkan asset dengan transition yang require approval. | J40: 1. Buka Lifecycle Panel. 2. Pilih target state yang butuh approval. 3. Submit transition. 4. Buka modul Approvals untuk memeriksa request. | K40: - Approval baru terbentuk. - Asset belum berpindah ke state final sebelum approval diputuskan. - Setelah approval disetujui, state berubah sesuai workflow. | L40: transition require approval | M40: Not Started | N40: V | P40: https://raw.githubusercontent.com/MuhamadRamdhani/ITAM/main/docs/diagram-per-modul.md
A41: ASSET-020 | B41: Core ITAM | C41: Assets | D41: Lifecycle Panel | E41: Memastikan UI menampilkan blocked reasons, gate rules, atau evidence required pada transition tertentu. | F41: Negative | G41: TENANT_ADMIN/ITAM_MANAGER | H41: Medium | I41: Siapkan asset yang belum memenuhi gate transition. | J41: 1. Buka Lifecycle Panel. 2. Pilih atau lihat transition yang terblokir. 3. Amati indikator atau alasan blokir. | K41: - User melihat alasan mengapa transition belum bisa dilakukan. - Bila evidence required, indikatornya jelas. - UI membantu user memperbaiki prasyarat sebelum submit. | L41: asset belum memenuhi gate | M41: Not Started | N41: V | P41: https://raw.githubusercontent.com/MuhamadRamdhani/ITAM/main/docs/panduan-penggunaan-lengkap.md
...

Sheet Ringkasan
A1: Ringkasan Coverage Testing
A2: Gunakan sheet ini untuk melihat jumlah skenario per modul, prioritas, dan status eksekusi.
A4: Modul | B4: Area | C4: Total | D4: High | E4: Medium | F4: Low | G4: Pass | H4: Fail | I4: Blocked | J4: Not Started | L4: Ringkasan Alur per Role
A5: Auth and Dashboard | B5: Fondasi | C5: =COUNTIF(Semua_Skenario!$C:$C,A5) -> 17 | D5: =COUNTIFS(Semua_Skenario!$C:$C,A5,Semua_Skenario!$H:$H,"High") -> 14 | E5: =COUNTIFS(Semua_Skenario!$C:$C,A5,Semua_Skenario!$H:$H,"Medium") -> 3 | F5: =COUNTIFS(Semua_Skenario!$C:$C,A5,Semua_Skenario!$H:$H,"Low") -> 0 | G5: =COUNTIFS(Semua_Skenario!$C:$C,A5,Semua_Skenario!$M:$M,"Pass") -> 0 | H5: =COUNTIFS(Semua_Skenario!$C:$C,A5,Semua_Skenario!$M:$M,"Fail") -> 0 | I5: =COUNTIFS(Semua_Skenario!$C:$C,A5,Semua_Skenario!$M:$M,"Blocked") -> 0 | J5: =COUNTIFS(Semua_Skenario!$C:$C,A5,Semua_Skenario!$M:$M,"Not Started") -> 17 | L5: Role | M5: Total Alur | N5: High | O5: Not Started | P5: Pass
A6: Assets | B6: Core ITAM | C6: =COUNTIF(Semua_Skenario!$C:$C,A6) -> 25 | D6: =COUNTIFS(Semua_Skenario!$C:$C,A6,Semua_Skenario!$H:$H,"High") -> 15 | E6: =COUNTIFS(Semua_Skenario!$C:$C,A6,Semua_Skenario!$H:$H,"Medium") -> 10 | F6: =COUNTIFS(Semua_Skenario!$C:$C,A6,Semua_Skenario!$H:$H,"Low") -> 0 | G6: =COUNTIFS(Semua_Skenario!$C:$C,A6,Semua_Skenario!$M:$M,"Pass") -> 0 | H6: =COUNTIFS(Semua_Skenario!$C:$C,A6,Semua_Skenario!$M:$M,"Fail") -> 0 | I6: =COUNTIFS(Semua_Skenario!$C:$C,A6,Semua_Skenario!$M:$M,"Blocked") -> 0 | J6: =COUNTIFS(Semua_Skenario!$C:$C,A6,Semua_Skenario!$M:$M,"Not Started") -> 25 | L6: Public | M6: =COUNTIF(Alur_Per_Role!$B:$B,L6) -> 3 | N6: =COUNTIFS(Alur_Per_Role!$B:$B,L6,Alur_Per_Role!$L:$L,"High") -> 3 | O6: =COUNTIFS(Alur_Per_Role!$B:$B,L6,Alur_Per_Role!$M:$M,"Not Started") -> 3 | P6: =COUNTIFS(Alur_Per_Role!$B:$B,L6,Alur_Per_Role!$M:$M,"Pass") -> 0
A7: Approvals | B7: Core ITAM | C7: =COUNTIF(Semua_Skenario!$C:$C,A7) -> 12 | D7: =COUNTIFS(Semua_Skenario!$C:$C,A7,Semua_Skenario!$H:$H,"High") -> 8 | E7: =COUNTIFS(Semua_Skenario!$C:$C,A7,Semua_Skenario!$H:$H,"Medium") -> 4 | F7: =COUNTIFS(Semua_Skenario!$C:$C,A7,Semua_Skenario!$H:$H,"Low") -> 0 | G7: =COUNTIFS(Semua_Skenario!$C:$C,A7,Semua_Skenario!$M:$M,"Pass") -> 0 | H7: =COUNTIFS(Semua_Skenario!$C:$C,A7,Semua_Skenario!$M:$M,"Fail") -> 0 | I7: =COUNTIFS(Semua_Skenario!$C:$C,A7,Semua_Skenario!$M:$M,"Blocked") -> 0 | J7: =COUNTIFS(Semua_Skenario!$C:$C,A7,Semua_Skenario!$M:$M,"Not Started") -> 12 | L7: Semua role login | M7: =COUNTIF(Alur_Per_Role!$B:$B,L7) -> 2 | N7: =COUNTIFS(Alur_Per_Role!$B:$B,L7,Alur_Per_Role!$L:$L,"High") -> 2 | O7: =COUNTIFS(Alur_Per_Role!$B:$B,L7,Alur_Per_Role!$M:$M,"Not Started") -> 2 | P7: =COUNTIFS(Alur_Per_Role!$B:$B,L7,Alur_Per_Role!$M:$M,"Pass") -> 0
A8: Documents | B8: Dokumen & Bukti | C8: =COUNTIF(Semua_Skenario!$C:$C,A8) -> 12 | D8: =COUNTIFS(Semua_Skenario!$C:$C,A8,Semua_Skenario!$H:$H,"High") -> 8 | E8: =COUNTIFS(Semua_Skenario!$C:$C,A8,Semua_Skenario!$H:$H,"Medium") -> 4 | F8: =COUNTIFS(Semua_Skenario!$C:$C,A8,Semua_Skenario!$H:$H,"Low") -> 0 | G8: =COUNTIFS(Semua_Skenario!$C:$C,A8,Semua_Skenario!$M:$M,"Pass") -> 0 | H8: =COUNTIFS(Semua_Skenario!$C:$C,A8,Semua_Skenario!$M:$M,"Fail") -> 0 | I8: =COUNTIFS(Semua_Skenario!$C:$C,A8,Semua_Skenario!$M:$M,"Blocked") -> 0 | J8: =COUNTIFS(Semua_Skenario!$C:$C,A8,Semua_Skenario!$M:$M,"Not Started") -> 12 | L8: SUPERADMIN | M8: =COUNTIF(Alur_Per_Role!$B:$B,L8) -> 4 | N8: =COUNTIFS(Alur_Per_Role!$B:$B,L8,Alur_Per_Role!$L:$L,"High") -> 4 | O8: =COUNTIFS(Alur_Per_Role!$B:$B,L8,Alur_Per_Role!$M:$M,"Not Started") -> 4 | P8: =COUNTIFS(Alur_Per_Role!$B:$B,L8,Alur_Per_Role!$M:$M,"Pass") -> 0
A9: Evidence | B9: Dokumen & Bukti | C9: =COUNTIF(Semua_Skenario!$C:$C,A9) -> 10 | D9: =COUNTIFS(Semua_Skenario!$C:$C,A9,Semua_Skenario!$H:$H,"High") -> 4 | E9: =COUNTIFS(Semua_Skenario!$C:$C,A9,Semua_Skenario!$H:$H,"Medium") -> 5 | F9: =COUNTIFS(Semua_Skenario!$C:$C,A9,Semua_Skenario!$H:$H,"Low") -> 1 | G9: =COUNTIFS(Semua_Skenario!$C:$C,A9,Semua_Skenario!$M:$M,"Pass") -> 0 | H9: =COUNTIFS(Semua_Skenario!$C:$C,A9,Semua_Skenario!$M:$M,"Fail") -> 0 | I9: =COUNTIFS(Semua_Skenario!$C:$C,A9,Semua_Skenario!$M:$M,"Blocked") -> 0 | J9: =COUNTIFS(Semua_Skenario!$C:$C,A9,Semua_Skenario!$M:$M,"Not Started") -> 10 | L9: TENANT_ADMIN | M9: =COUNTIF(Alur_Per_Role!$B:$B,L9) -> 24 | N9: =COUNTIFS(Alur_Per_Role!$B:$B,L9,Alur_Per_Role!$L:$L,"High") -> 23 | O9: =COUNTIFS(Alur_Per_Role!$B:$B,L9,Alur_Per_Role!$M:$M,"Not Started") -> 24 | P9: =COUNTIFS(Alur_Per_Role!$B:$B,L9,Alur_Per_Role!$M:$M,"Pass") -> 0
A10: Audit Events | B10: Dokumen & Bukti | C10: =COUNTIF(Semua_Skenario!$C:$C,A10) -> 8 | D10: =COUNTIFS(Semua_Skenario!$C:$C,A10,Semua_Skenario!$H:$H,"High") -> 4 | E10: =COUNTIFS(Semua_Skenario!$C:$C,A10,Semua_Skenario!$H:$H,"Medium") -> 4 | F10: =COUNTIFS(Semua_Skenario!$C:$C,A10,Semua_Skenario!$H:$H,"Low") -> 0 | G10: =COUNTIFS(Semua_Skenario!$C:$C,A10,Semua_Skenario!$M:$M,"Pass") -> 0 | H10: =COUNTIFS(Semua_Skenario!$C:$C,A10,Semua_Skenario!$M:$M,"Fail") -> 0 | I10: =COUNTIFS(Semua_Skenario!$C:$C,A10,Semua_Skenario!$M:$M,"Blocked") -> 0 | J10: =COUNTIFS(Semua_Skenario!$C:$C,A10,Semua_Skenario!$M:$M,"Not Started") -> 8 | L10: ITAM_MANAGER | M10: =COUNTIF(Alur_Per_Role!$B:$B,L10) -> 22 | N10: =COUNTIFS(Alur_Per_Role!$B:$B,L10,Alur_Per_Role!$L:$L,"High") -> 11 | O10: =COUNTIFS(Alur_Per_Role!$B:$B,L10,Alur_Per_Role!$M:$M,"Not Started") -> 22 | P10: =COUNTIFS(Alur_Per_Role!$B:$B,L10,Alur_Per_Role!$M:$M,"Pass") -> 0
A11: Governance | B11: Governance & Assurance | C11: =COUNTIF(Semua_Skenario!$C:$C,A11) -> 12 | D11: =COUNTIFS(Semua_Skenario!$C:$C,A11,Semua_Skenario!$H:$H,"High") -> 6 | E11: =COUNTIFS(Semua_Skenario!$C:$C,A11,Semua_Skenario!$H:$H,"Medium") -> 4 | F11: =COUNTIFS(Semua_Skenario!$C:$C,A11,Semua_Skenario!$H:$H,"Low") -> 2 | G11: =COUNTIFS(Semua_Skenario!$C:$C,A11,Semua_Skenario!$M:$M,"Pass") -> 0 | H11: =COUNTIFS(Semua_Skenario!$C:$C,A11,Semua_Skenario!$M:$M,"Fail") -> 0 | I11: =COUNTIFS(Semua_Skenario!$C:$C,A11,Semua_Skenario!$M:$M,"Blocked") -> 0 | J11: =COUNTIFS(Semua_Skenario!$C:$C,A11,Semua_Skenario!$M:$M,"Not Started") -> 12 | L11: PROCUREMENT_CONTRACT_MANAGER | M11: =COUNTIF(Alur_Per_Role!$B:$B,L11) -> 8 | N11: =COUNTIFS(Alur_Per_Role!$B:$B,L11,Alur_Per_Role!$L:$L,"High") -> 8 | O11: =COUNTIFS(Alur_Per_Role!$B:$B,L11,Alur_Per_Role!$M:$M,"Not Started") -> 8 | P11: =COUNTIFS(Alur_Per_Role!$B:$B,L11,Alur_Per_Role!$M:$M,"Pass") -> 0
A12: Vendors | B12: Komersial & Lisensi | C12: =COUNTIF(Semua_Skenario!$C:$C,A12) -> 10 | D12: =COUNTIFS(Semua_Skenario!$C:$C,A12,Semua_Skenario!$H:$H,"High") -> 5 | E12: =COUNTIFS(Semua_Skenario!$C:$C,A12,Semua_Skenario!$H:$H,"Medium") -> 5 | F12: =COUNTIFS(Semua_Skenario!$C:$C,A12,Semua_Skenario!$H:$H,"Low") -> 0 | G12: =COUNTIFS(Semua_Skenario!$C:$C,A12,Semua_Skenario!$M:$M,"Pass") -> 0 | H12: =COUNTIFS(Semua_Skenario!$C:$C,A12,Semua_Skenario!$M:$M,"Fail") -> 0 | I12: =COUNTIFS(Semua_Skenario!$C:$C,A12,Semua_Skenario!$M:$M,"Blocked") -> 0 | J12: =COUNTIFS(Semua_Skenario!$C:$C,A12,Semua_Skenario!$M:$M,"Not Started") -> 10 | L12: ASSET_CUSTODIAN | M12: =COUNTIF(Alur_Per_Role!$B:$B,L12) -> 6 | N12: =COUNTIFS(Alur_Per_Role!$B:$B,L12,Alur_Per_Role!$L:$L,"High") -> 3 | O12: =COUNTIFS(Alur_Per_Role!$B:$B,L12,Alur_Per_Role!$M:$M,"Not Started") -> 6 | P12: =COUNTIFS(Alur_Per_Role!$B:$B,L12,Alur_Per_Role!$M:$M,"Pass") -> 0
A13: Contracts | B13: Komersial & Lisensi | C13: =COUNTIF(Semua_Skenario!$C:$C,A13) -> 12 | D13: =COUNTIFS(Semua_Skenario!$C:$C,A13,Semua_Skenario!$H:$H,"High") -> 5 | E13: =COUNTIFS(Semua_Skenario!$C:$C,A13,Semua_Skenario!$H:$H,"Medium") -> 7 | F13: =COUNTIFS(Semua_Skenario!$C:$C,A13,Semua_Skenario!$H:$H,"Low") -> 0 | G13: =COUNTIFS(Semua_Skenario!$C:$C,A13,Semua_Skenario!$M:$M,"Pass") -> 0 | H13: =COUNTIFS(Semua_Skenario!$C:$C,A13,Semua_Skenario!$M:$M,"Fail") -> 0 | I13: =COUNTIFS(Semua_Skenario!$C:$C,A13,Semua_Skenario!$M:$M,"Blocked") -> 0 | J13: =COUNTIFS(Semua_Skenario!$C:$C,A13,Semua_Skenario!$M:$M,"Not Started") -> 12 | L13: AUDITOR | M13: =COUNTIF(Alur_Per_Role!$B:$B,L13) -> 7 | N13: =COUNTIFS(Alur_Per_Role!$B:$B,L13,Alur_Per_Role!$L:$L,"High") -> 3 | O13: =COUNTIFS(Alur_Per_Role!$B:$B,L13,Alur_Per_Role!$M:$M,"Not Started") -> 7 | P13: =COUNTIFS(Alur_Per_Role!$B:$B,L13,Alur_Per_Role!$M:$M,"Pass") -> 0
A14: Software Products | B14: Komersial & Lisensi | C14: =COUNTIF(Semua_Skenario!$C:$C,A14) -> 12 | D14: =COUNTIFS(Semua_Skenario!$C:$C,A14,Semua_Skenario!$H:$H,"High") -> 7 | E14: =COUNTIFS(Semua_Skenario!$C:$C,A14,Semua_Skenario!$H:$H,"Medium") -> 5 | F14: =COUNTIFS(Semua_Skenario!$C:$C,A14,Semua_Skenario!$H:$H,"Low") -> 0 | G14: =COUNTIFS(Semua_Skenario!$C:$C,A14,Semua_Skenario!$M:$M,"Pass") -> 0 | H14: =COUNTIFS(Semua_Skenario!$C:$C,A14,Semua_Skenario!$M:$M,"Fail") -> 0 | I14: =COUNTIFS(Semua_Skenario!$C:$C,A14,Semua_Skenario!$M:$M,"Blocked") -> 0 | J14: =COUNTIFS(Semua_Skenario!$C:$C,A14,Semua_Skenario!$M:$M,"Not Started") -> 12 | L14: SECURITY_OFFICER | M14: =COUNTIF(Alur_Per_Role!$B:$B,L14) -> 1 | N14: =COUNTIFS(Alur_Per_Role!$B:$B,L14,Alur_Per_Role!$L:$L,"High") -> 0 | O14: =COUNTIFS(Alur_Per_Role!$B:$B,L14,Alur_Per_Role!$M:$M,"Not Started") -> 1 | P14: =COUNTIFS(Alur_Per_Role!$B:$B,L14,Alur_Per_Role!$M:$M,"Pass") -> 0
A15: Asset Transfer Requests | B15: Komersial & Lisensi | C15: =COUNTIF(Semua_Skenario!$C:$C,A15) -> 10 | D15: =COUNTIFS(Semua_Skenario!$C:$C,A15,Semua_Skenario!$H:$H,"High") -> 7 | E15: =COUNTIFS(Semua_Skenario!$C:$C,A15,Semua_Skenario!$H:$H,"Medium") -> 3 | F15: =COUNTIFS(Semua_Skenario!$C:$C,A15,Semua_Skenario!$H:$H,"Low") -> 0 | G15: =COUNTIFS(Semua_Skenario!$C:$C,A15,Semua_Skenario!$M:$M,"Pass") -> 0 | H15: =COUNTIFS(Semua_Skenario!$C:$C,A15,Semua_Skenario!$M:$M,"Fail") -> 0 | I15: =COUNTIFS(Semua_Skenario!$C:$C,A15,Semua_Skenario!$M:$M,"Blocked") -> 0 | J15: =COUNTIFS(Semua_Skenario!$C:$C,A15,Semua_Skenario!$M:$M,"Not Started") -> 10 | L15: SERVICE_DESK_OPERATOR | M15: =COUNTIF(Alur_Per_Role!$B:$B,L15) -> 0 | N15: =COUNTIFS(Alur_Per_Role!$B:$B,L15,Alur_Per_Role!$L:$L,"High") -> 0 | O15: =COUNTIFS(Alur_Per_Role!$B:$B,L15,Alur_Per_Role!$M:$M,"Not Started") -> 0 | P15: =COUNTIFS(Alur_Per_Role!$B:$B,L15,Alur_Per_Role!$M:$M,"Pass") -> 0
A16: KPI Library and Scorecard | B16: Governance & Assurance | C16: =COUNTIF(Semua_Skenario!$C:$C,A16) -> 12 | D16: =COUNTIFS(Semua_Skenario!$C:$C,A16,Semua_Skenario!$H:$H,"High") -> 5 | E16: =COUNTIFS(Semua_Skenario!$C:$C,A16,Semua_Skenario!$H:$H,"Medium") -> 7 | F16: =COUNTIFS(Semua_Skenario!$C:$C,A16,Semua_Skenario!$H:$H,"Low") -> 0 | G16: =COUNTIFS(Semua_Skenario!$C:$C,A16,Semua_Skenario!$M:$M,"Pass") -> 0 | H16: =COUNTIFS(Semua_Skenario!$C:$C,A16,Semua_Skenario!$M:$M,"Fail") -> 0 | I16: =COUNTIFS(Semua_Skenario!$C:$C,A16,Semua_Skenario!$M:$M,"Blocked") -> 0 | J16: =COUNTIFS(Semua_Skenario!$C:$C,A16,Semua_Skenario!$M:$M,"Not Started") -> 12 | L16: INTEGRATION_USER | M16: =COUNTIF(Alur_Per_Role!$B:$B,L16) -> 0 | N16: =COUNTIFS(Alur_Per_Role!$B:$B,L16,Alur_Per_Role!$L:$L,"High") -> 0 | O16: =COUNTIFS(Alur_Per_Role!$B:$B,L16,Alur_Per_Role!$M:$M,"Not Started") -> 0 | P16: =COUNTIFS(Alur_Per_Role!$B:$B,L16,Alur_Per_Role!$M:$M,"Pass") -> 0
A17: Internal Audits | B17: Governance & Assurance | C17: =COUNTIF(Semua_Skenario!$C:$C,A17) -> 12 | D17: =COUNTIFS(Semua_Skenario!$C:$C,A17,Semua_Skenario!$H:$H,"High") -> 7 | E17: =COUNTIFS(Semua_Skenario!$C:$C,A17,Semua_Skenario!$H:$H,"Medium") -> 5 | F17: =COUNTIFS(Semua_Skenario!$C:$C,A17,Semua_Skenario!$H:$H,"Low") -> 0 | G17: =COUNTIFS(Semua_Skenario!$C:$C,A17,Semua_Skenario!$M:$M,"Pass") -> 0 | H17: =COUNTIFS(Semua_Skenario!$C:$C,A17,Semua_Skenario!$M:$M,"Fail") -> 0 | I17: =COUNTIFS(Semua_Skenario!$C:$C,A17,Semua_Skenario!$M:$M,"Blocked") -> 0 | J17: =COUNTIFS(Semua_Skenario!$C:$C,A17,Semua_Skenario!$M:$M,"Not Started") -> 12
A18: Management Reviews | B18: Governance & Assurance | C18: =COUNTIF(Semua_Skenario!$C:$C,A18) -> 12 | D18: =COUNTIFS(Semua_Skenario!$C:$C,A18,Semua_Skenario!$H:$H,"High") -> 6 | E18: =COUNTIFS(Semua_Skenario!$C:$C,A18,Semua_Skenario!$H:$H,"Medium") -> 6 | F18: =COUNTIFS(Semua_Skenario!$C:$C,A18,Semua_Skenario!$H:$H,"Low") -> 0 | G18: =COUNTIFS(Semua_Skenario!$C:$C,A18,Semua_Skenario!$M:$M,"Pass") -> 0 | H18: =COUNTIFS(Semua_Skenario!$C:$C,A18,Semua_Skenario!$M:$M,"Fail") -> 0 | I18: =COUNTIFS(Semua_Skenario!$C:$C,A18,Semua_Skenario!$M:$M,"Blocked") -> 0 | J18: =COUNTIFS(Semua_Skenario!$C:$C,A18,Semua_Skenario!$M:$M,"Not Started") -> 12
A19: Reports | B19: Governance & Assurance | C19: =COUNTIF(Semua_Skenario!$C:$C,A19) -> 9 | D19: =COUNTIFS(Semua_Skenario!$C:$C,A19,Semua_Skenario!$H:$H,"High") -> 6 | E19: =COUNTIFS(Semua_Skenario!$C:$C,A19,Semua_Skenario!$H:$H,"Medium") -> 3 | F19: =COUNTIFS(Semua_Skenario!$C:$C,A19,Semua_Skenario!$H:$H,"Low") -> 0 | G19: =COUNTIFS(Semua_Skenario!$C:$C,A19,Semua_Skenario!$M:$M,"Pass") -> 0 | H19: =COUNTIFS(Semua_Skenario!$C:$C,A19,Semua_Skenario!$M:$M,"Fail") -> 0 | I19: =COUNTIFS(Semua_Skenario!$C:$C,A19,Semua_Skenario!$M:$M,"Blocked") -> 0 | J19: =COUNTIFS(Semua_Skenario!$C:$C,A19,Semua_Skenario!$M:$M,"Not Started") -> 9
A20: Admin Master Data | B20: Admin & Platform | C20: =COUNTIF(Semua_Skenario!$C:$C,A20) -> 12 | D20: =COUNTIFS(Semua_Skenario!$C:$C,A20,Semua_Skenario!$H:$H,"High") -> 5 | E20: =COUNTIFS(Semua_Skenario!$C:$C,A20,Semua_Skenario!$H:$H,"Medium") -> 7 | F20: =COUNTIFS(Semua_Skenario!$C:$C,A20,Semua_Skenario!$H:$H,"Low") -> 0 | G20: =COUNTIFS(Semua_Skenario!$C:$C,A20,Semua_Skenario!$M:$M,"Pass") -> 0 | H20: =COUNTIFS(Semua_Skenario!$C:$C,A20,Semua_Skenario!$M:$M,"Fail") -> 0 | I20: =COUNTIFS(Semua_Skenario!$C:$C,A20,Semua_Skenario!$M:$M,"Blocked") -> 0 | J20: =COUNTIFS(Semua_Skenario!$C:$C,A20,Semua_Skenario!$M:$M,"Not Started") -> 12
A21: Superadmin Tenants | B21: Admin & Platform | C21: =COUNTIF(Semua_Skenario!$C:$C,A21) -> 10 | D21: =COUNTIFS(Semua_Skenario!$C:$C,A21,Semua_Skenario!$H:$H,"High") -> 9 | E21: =COUNTIFS(Semua_Skenario!$C:$C,A21,Semua_Skenario!$H:$H,"Medium") -> 1 | F21: =COUNTIFS(Semua_Skenario!$C:$C,A21,Semua_Skenario!$H:$H,"Low") -> 0 | G21: =COUNTIFS(Semua_Skenario!$C:$C,A21,Semua_Skenario!$M:$M,"Pass") -> 0 | H21: =COUNTIFS(Semua_Skenario!$C:$C,A21,Semua_Skenario!$M:$M,"Fail") -> 0 | I21: =COUNTIFS(Semua_Skenario!$C:$C,A21,Semua_Skenario!$M:$M,"Blocked") -> 0 | J21: =COUNTIFS(Semua_Skenario!$C:$C,A21,Semua_Skenario!$M:$M,"Not Started") -> 10
A22: CAPA | B22: Governance & Assurance | C22: =COUNTIF(Semua_Skenario!$C:$C,A22) -> 36 | D22: =COUNTIFS(Semua_Skenario!$C:$C,A22,Semua_Skenario!$H:$H,"High") -> 23 | E22: =COUNTIFS(Semua_Skenario!$C:$C,A22,Semua_Skenario!$H:$H,"Medium") -> 11 | F22: =COUNTIFS(Semua_Skenario!$C:$C,A22,Semua_Skenario!$H:$H,"Low") -> 2 | G22: =COUNTIFS(Semua_Skenario!$C:$C,A22,Semua_Skenario!$M:$M,"Pass") -> 0 | H22: =COUNTIFS(Semua_Skenario!$C:$C,A22,Semua_Skenario!$M:$M,"Fail") -> 0 | I22: =COUNTIFS(Semua_Skenario!$C:$C,A22,Semua_Skenario!$M:$M,"Blocked") -> 0 | J22: =COUNTIFS(Semua_Skenario!$C:$C,A22,Semua_Skenario!$M:$M,"Not Started") -> 36

Sheet Alur_Per_Role
A1: ITAM - Alur Testing per Role
A2: Sheet ini menjawab pola: siapa yang login → masuk ke modul mana → melakukan apa → fitur itu dipakai untuk apa → setelah itu masuk ke detail mana → di detail harus mengecek apa.
A4: No | B4: Role Login | C4: Masuk ke Modul | D4: Halaman / Menu | E4: Setelah Itu Masuk Ke | F4: Aksi User | G4: Penjelasan Fitur yang Dipakai | H4: Setelah Aksi Sukses | I4: Fitur di Halaman Detail | J4: Fungsi Fitur Detail / Yang Dicek | K4: Expected Outcome | L4: Prioritas | M4: Status Eksekusi | N4: Actual Result | O4: Catatan | P4: Sumber Acuan
A5: 1 | B5: Public | C5: Login | D5: Halaman Login | E5: Home / Dashboard | F5: Isi `Tenant Code`, `Email Address`, `Password`, lalu selesaikan captcha dan klik login. | G5: Fitur login dipakai untuk masuk ke tenant yang benar. Sistem memeriksa status tenant, kontrak, dan captcha sebelum sesi dibuat. | H5: Dashboard terbuka setelah login sukses. | I5: Summary cards, launcher modul, quick links | J5: Verifikasi summary tampil, launcher sesuai role, dan user bisa lanjut ke modul lain. | K5: Sesi cookie terbentuk; redirect ke `/`; data `/auth/me` dan dashboard berhasil dimuat. | L5: High | M5: Not Started | P5: https://raw.githubusercontent.com/MuhamadRamdhani/ITAM/main/docs/panduan-penggunaan-lengkap.md
A6: 2 | B6: Semua role login | C6: Home / Dashboard | D6: Home / Dashboard | E6: Modul yang sesuai role | F6: Baca summary cards lalu klik launcher/quick links yang tersedia. | G6: Dashboard adalah hub operasional. Bukan untuk membuat data bisnis baru, tetapi untuk melihat kondisi tenant dan masuk ke modul yang relevan. | H6: Masuk ke modul tujuan. | I6: Launcher role-based, quick links, vendor contract alert | J6: Cek launcher hanya menampilkan area yang relevan, dan quick link menuju halaman yang benar. | K6: User bisa memakai dashboard sebagai pintu masuk utama tanpa error navigasi. | L6: High | M6: Not Started | P6: https://raw.githubusercontent.com/MuhamadRamdhani/ITAM/main/docs/diagram-per-modul.md
A7: 3 | B7: TENANT_ADMIN | C7: Assets | D7: Assets List | E7: New Asset | F7: Buka Assets lalu klik `New Asset`. | G7: Assets List dipakai untuk melihat, mencari, dan memfilter aset berdasarkan type dan lifecycle state. New Asset dipakai untuk registrasi aset baru. | H7: Form New Asset tampil. | I7: Field create: Asset Tag, Name, Asset Type, Initial State, Status, coverage dates | J7: Isi field inti dan cek dropdown diambil dari config/master tenant. | K7: Form create terbuka dan siap dipakai membuat data asset baru. | L7: High | M7: Not Started | P7: https://raw.githubusercontent.com/MuhamadRamdhani/ITAM/main/docs/panduan-penggunaan-lengkap.md
A8: 4 | B8: TENANT_ADMIN | C8: Assets | D8: New Asset | E8: Asset Detail | F8: Isi data asset lalu simpan. | G8: Create Asset dipakai untuk membuat record asset baru. Coverage field harus mengikuti jenis asset, misalnya warranty/support untuk hardware dan subscription untuk software/saas. | H8: Masuk ke Asset Detail. | I8: Ownership Panel, Lifecycle Panel, Software Installations Panel, Software Assignments Modal | J8: Pahami bahwa Asset Detail adalah hub utama yang menghubungkan ownership, lifecycle, software, dan workflow lain. | K8: Asset tersimpan dan user masuk ke halaman detail asset yang baru dibuat. | L8: High | M8: Not Started | P8: https://raw.githubusercontent.com/MuhamadRamdhani/ITAM/main/docs/diagram-per-modul.md
A9: 5 | B9: ASSET_CUSTODIAN | C9: Assets | D9: Asset Detail | E9: Tetap di Asset Detail | F9: Buka panel `Ownership` lalu ubah owner department, custodian identity, atau location bila diizinkan. | G9: Ownership Panel dipakai untuk menjaga siapa owner, siapa custodian, dan di lokasi mana asset berada. Perubahan ownership harus menyisakan jejak history. | H9: Tetap di Asset Detail. | I9: Department selector, Identity selector, Location selector, Reason | J9: Isi lookup department/identity/location dengan benar; Reason bisa dipakai untuk menjelaskan perubahan. | K9: Ownership aktif berubah dan riwayat ownership dapat dilihat. | L9: High | M9: Not Started | P9: https://raw.githubusercontent.com/MuhamadRamdhani/ITAM/main/docs/panduan-penggunaan-lengkap.md
A10: 6 | B10: ITAM_MANAGER | C10: Assets | D10: Asset Detail | E10: Tetap di Asset Detail | F10: Buka panel `Lifecycle`, pilih target state, lalu submit transition. | G10: Lifecycle dipakai untuk mengendalikan status operasional aset. Beberapa transition bisa membutuhkan approval, evidence, atau gate rules sebelum perubahan diterapkan. | H10: Bisa tetap di detail atau lanjut ke Approvals bila perlu. | I10: Target State, indicator approval required/evidence required/gate rules/blocked reasons | J10: Cek apakah target state tersedia, apa syaratnya, dan apakah state berubah langsung atau menunggu approval. | K10: Current state/history terbaca; transition berhasil atau membuat approval bila memang diwajibkan. | L10: High | M10: Not Started | P10: https://raw.githubusercontent.com/MuhamadRamdhani/ITAM/main/docs/panduan-penggunaan-lengkap.md
A11: 7 | B11: ITAM_MANAGER | C11: Assets | D11: Asset Detail | E11: Tetap di Asset Detail | F11: Buka `Software Installations`, tambah installation untuk asset yang sedang dibuka. | G11: Panel ini dipakai untuk mencatat software yang terpasang pada sebuah asset. Ini penting untuk jejak penggunaan software dan analisis compliance. | H11: Masih di Asset Detail. | I11: Software Product, Installation Status, Installed Version, Installation Date, Discovery Source | J11: Isi product, status, versi, tanggal, dan catatan agar jejak instalasi lengkap. | K11: Installation baru tercatat dan bisa dibaca kembali di panel installation history. | L11: Medium | M11: Not Started | P11: https://raw.githubusercontent.com/MuhamadRamdhani/ITAM/main/docs/panduan-penggunaan-lengkap.md
A12: 8 | B12: ITAM_MANAGER | C12: Assets | D12: Asset Detail | E12: Software Assignments Modal | F12: Buka assignment pada salah satu installation lalu kaitkan identity. | G12: Software Assignments dipakai untuk mencatat software tersebut digunakan oleh siapa dan dalam peran apa, misalnya primary user atau service account. | H12: Tetap di detail asset/installasi. | I12: Identity, Assignment Role, Assignment Status, Assigned At, Notes | J12: Pilih identity yang benar dan tentukan role assignment sesuai penggunaan nyata. | K12: Identity berhasil terhubung ke installation dan status assignment dapat dibaca. | L12: Medium | M12: Not Started | P12: https://raw.githubusercontent.com/MuhamadRamdhani/ITAM/main/docs/panduan-penggunaan-lengkap.md
A13: 9 | B13: TENANT_ADMIN | C13: Approvals | D13: Approvals List | E13: Approval Detail | F13: Buka queue approvals, filter status, lalu buka salah satu approval. | G13: Approvals adalah gate untuk workflow lain. User biasanya memantau antrian approval dan membuka detail untuk memutuskan approve atau reject. | H13: Tetap di Approvals atau kembali ke modul asal. | I13: Status filter, detail approval, action Approve/Reject | J13: Cek sumber approval, statusnya, dan konsekuensinya ke workflow asal. | K13: Queue dapat difilter dan detail approval terbuka sesuai tenant. | L13: High | M13: Not Started | P13: https://raw.githubusercontent.com/MuhamadRamdhani/ITAM/main/docs/diagram-per-modul.md
A14: 10 | B14: PROCUREMENT_CONTRACT_MANAGER | C14: Approvals | D14: Approval Detail | E14: Workflow asal | F14: Klik `Approve` atau `Reject` pada approval yang menjadi kewenangannya. | G14: Decision action dipakai untuk menyetujui atau menolak workflow yang membutuhkan persetujuan. Khusus procurement, ini sering berkaitan dengan area kontrak atau workflow yang serupa. | H14: Kembali ke modul asal / queue approvals. | I14: Decision action, decision note | J14: Isi note bila diperlukan dan cek perubahan status approval serta dampaknya ke workflow sumber. | K14: Status approval berubah dan workflow asal menerima hasil keputusan. | L14: High | M14: Not Started | P14: https://raw.githubusercontent.com/MuhamadRamdhani/ITAM/main/docs/matriks-akses-role.md
A15: 11 | B15: ITAM_MANAGER | C15: Documents | D15: Documents List | E15: New Document | F15: Buka modul Documents lalu pilih create/new document. | G15: Documents dipakai untuk mengelola dokumen tenant dengan workflow versioning dari draft sampai published/archived. | H15: Document Detail / list document. | I15: Field create: doc_type_code, title, content_json | J15: Isi jenis dokumen, judul, dan konten awal sebagai draft pertama. | K15: Dokumen baru terbentuk dalam status draft atau sesuai workflow awal sistem. | L15: High | M15: Not Started | P15: https://raw.githubusercontent.com/MuhamadRamdhani/ITAM/main/docs/panduan-penggunaan-lengkap.md
A16: 12 | B16: ITAM_MANAGER | C16: Documents | D16: Document Detail | E16: Tetap di Document Detail | F16: Submit dokumen dari `DRAFT` ke `IN_REVIEW`, lalu revisi bila perlu. | G16: Detail document adalah tempat membaca isi, mengelola versi, dan menjalankan workflow dokumen. User operasional biasanya fokus membuat, memperbarui, lalu submit. | H16: Bisa lanjut ke approval/publish oleh admin. | I16: Versioning, status workflow, content update | J16: Cek perubahan status, kemampuan edit, dan konsistensi versi setelah submit/revisi. | K16: Dokumen bergerak ke tahap review dengan jejak workflow yang jelas. | L16: High | M16: Not Started | P16: https://raw.githubusercontent.com/MuhamadRamdhani/ITAM/main/docs/panduan-penggunaan-lengkap.md
... A88: 87 | B88: SECURITY_OFFICER | C88: CAPA | D88: CAPA Detail | E88: Cancel CAPA | F88: Isi cancel reason bila kasus harus dibatalkan, lalu klik Cancel CAPA. | G88: Cancel dipakai bila kasus tidak lagi relevan atau perlu dihentikan secara resmi. | H88: Status CAPA berubah ke CANCELLED. | I88: Cancel box, notes/cancel reason, cancelled_at | J88: Cek cancel hanya tidak boleh dilakukan pada CAPA CLOSED dan pembatalan menambah jejak catatan. | K88: Kasus CAPA dibatalkan secara resmi dengan jejak audit yang jelas. | L88: Medium | M88: Not Started | P88: https://raw.githubusercontent.com/MuhamadRamdhani/ITAM/main/apps/api/src/modules/capa/capa.service.js

Sheet Matriks_Role_Modul
A1: ITAM - Matriks Role vs Modul
A2: Gunakan sheet ini untuk melihat siapa yang punya hak baca/tulis/special action di setiap modul. Nilai mengikuti ringkasan role yang terlihat di repo saat ini.
A4: Modul / Area | B4: SUPERADMIN | C4: TENANT_ADMIN | D4: ITAM_MANAGER | E4: PROCUREMENT_CONTRACT_MANAGER | F4: ASSET_CUSTODIAN | G4: AUDITOR | H4: SECURITY_OFFICER | I4: SERVICE_DESK_OPERATOR | J4: INTEGRATION_USER | K4: Catatan
A5: Login / Auth | B5: P | C5: P | D5: P | E5: P | F5: P | G5: P | H5: P | I5: P | J5: P | K5: Public login; sesudah itu tenant context berlaku
A6: Home / Dashboard | B6: P | C6: P | D6: P | E6: P | F6: P | G6: P | H6: - | I6: - | J6: - | K6: Launcher mengikuti role user
A7: Assets | B7: P/W | C7: P/W | D7: P/W | E7: P | F7: P/W(S) | G7: P | H7: - | I7: - | J7: - | K7: Create/edit butuh role operasional; custodian punya special action tertentu
A8: Approvals | B8: P | C8: P/W(S) | D8: P/W(S) | E8: P/W(S) | F8: P | G8: P | H8: - | I8: - | J8: - | K8: Decision dibatasi role tertentu
A9: Documents | B9: P | C9: P/W | D9: P/W | E9: - | F9: - | G9: P | H9: - | I9: - | J9: - | K9: Workflow draft → review → approve → publish
A10: Evidence | B10: P | C10: P/W | D10: P/W | E10: - | F10: P/W(S) | G10: P | H10: - | I10: - | J10: - | K10: Upload dan attach dibatasi role operasional
A11: Audit Events | B11: P | C11: P | D11: P | E11: - | F11: - | G11: P | H11: - | I11: - | J11: - | K11: Read-only
A12: Governance Scope | B12: P | C12: P/W | D12: P/W | E12: - | F12: - | G12: P | H12: - | I12: - | J12: - | K12: Scope version workflow
A13: Governance Context | B13: P | C13: P/W | D13: P/W | E13: - | F13: - | G13: P | H13: - | I13: - | J13: - | K13: Register context
A14: Governance Stakeholders | B14: P | C14: P/W | D14: P/W | E14: - | F14: - | G14: P | H14: - | I14: - | J14: - | K14: Register stakeholder
A15: Vendors | B15: P/W | C15: P/W | D15: P/W | E15: P/W | F15: - | G15: P | H15: - | I15: - | J15: - | K15: Vendor registry tenant-scoped
... A34: CAPA | B34: P/W | C34: P/W | D34: P/W | E34: - | F34: - | G34: P | H34: P/W | I34: - | J34: - | K34: View role mencakup AUDITOR; create/update/stage/close/cancel hanya role operasional.

Sheet Auth & Dashboard
A1: Skenario - Auth and Dashboard
A2: Gunakan sheet Alur_Per_Role untuk membaca flow user per role sebelum mengeksekusi test case detail di sheet ini.
A4: ID Skenario | B4: Kelompok Area | C4: Modul | D4: Fitur | E4: Tujuan Uji | F4: Jenis Uji | G4: Role Uji | H4: Prioritas | I4: Precondition | J4: Langkah Uji | K4: Hasil yang Diharapkan | L4: Data Uji | M4: Status Eksekusi | N4: Actual Result | O4: Catatan | P4: Sumber Acuan
A5: AUTH-001 | B5: Fondasi | C5: Auth and Dashboard | D5: Login | E5: Memastikan user dapat login dengan kredensial tenant yang valid. | F5: Positive | G5: Public | H5: High | I5: Tenant aktif; akun aktif; captcha dapat digunakan. | J5: 1. Buka halaman login. 2. Isi Tenant Code, Email Address, Password, dan captcha token. 3. Klik Sign In / Login. 4. Tunggu redirect ke home. | K5: - Session cookie terbentuk. - User diarahkan ke dashboard. - Data /auth/me berhasil dibaca dan shell aplikasi tampil. | L5: tenant code valid; email valid; password valid | M5: Not Started | P5: https://raw.githubusercontent.com/MuhamadRamdhani/ITAM/main/docs/panduan-penggunaan-lengkap.md
A6: AUTH-002 | B6: Fondasi | C6: Auth and Dashboard | D6: Login | E6: Memastikan login ditolak saat password salah. | F6: Negative | G6: Public | H6: High | I6: Tenant aktif; akun ada. | J6: 1. Buka halaman login. 2. Isi Tenant Code dan Email valid, tetapi Password salah. 3. Selesaikan captcha. 4. Submit form login. | K6: - Login ditolak. - Pesan error tampil. - Tidak ada redirect ke dashboard dan sesi tidak dibuat. | L6: password invalid | M6: Not Started | P6: https://raw.githubusercontent.com/MuhamadRamdhani/ITAM/main/docs/panduan-penggunaan-lengkap.md
A7: AUTH-003 | B7: Fondasi | C7: Auth and Dashboard | D7: Login | E7: Memastikan tenant dengan contract expired / suspended diblokir. | F7: Negative | G7: Public | H7: High | I7: Siapkan tenant expired atau suspended. | J7: 1. Buka halaman login. 2. Masukkan kredensial akun tenant expired atau suspended. 3. Selesaikan captcha dan submit. | K7: - Login ditolak. - Modal/penjelasan terkait contract atau suspension tampil. - User tetap berada di login page. | L7: tenant contract expired / tenant suspended | M7: Not Started | P7: https://raw.githubusercontent.com/MuhamadRamdhani/ITAM/main/docs/panduan-penggunaan-lengkap.md
A8: AUTH-004 | B8: Fondasi | C8: Auth and Dashboard | D8: Refresh Session | E8: Memastikan access token yang expired dapat dipulihkan otomatis dengan refresh. | F8: Integration | G8: All authenticated users | H8: High | I8: User sudah login; refresh token masih valid. | J8: 1. Biarkan access token expired atau simulasi request protected saat token access sudah tidak valid. 2. Akses halaman protected. 3. Amati request refresh dan retry request asal. | K8: - Client memanggil /auth/refresh. - Request protected diulang otomatis. - User tetap berada di halaman aplikasi tanpa login ulang. | M8: Not Started | O8: Sangat penting untuk regression auth wrapper. | P8: https://raw.githubusercontent.com/MuhamadRamdhani/ITAM/main/docs/alur-end-to-end-login-sampai-kpi-dan-internal-audit.md
A9: AUTH-005 | B9: Fondasi | C9: Auth and Dashboard | D9: Logout | E9: Memastikan logout mengakhiri sesi dengan aman. | F9: Positive | G9: All authenticated users | H9: High | I9: User sudah login. | J9: 1. Buka application shell. 2. Klik logout. 3. Tunggu redirect ke login. 4. Coba buka halaman protected kembali. | K9: - User kembali ke login. - Halaman protected tidak bisa diakses tanpa login ulang. - Sesi lama tidak dapat dipakai lagi. | M9: Not Started | P9: https://raw.githubusercontent.com/MuhamadRamdhani/ITAM/main/docs/generate-itam-test-scenarios.ps1
A10: AUTH-006 | B10: Fondasi | C10: Auth and Dashboard | D10: Dashboard | E10: Memastikan dashboard menampilkan summary cards dan quick links. | F10: Positive | G10: All authenticated users | H10: High | I10: User sudah login. | J10: 1. Buka home/dashboard. 2. Periksa summary cards. 3. Periksa quick links utama. 4. Klik satu quick link. | K10: - Summary cards tampil. - Quick links ke create asset/document/upload evidence terlihat sesuai peran. - Navigasi quick link berjalan. | M10: Not Started | P10: https://raw.githubusercontent.com/MuhamadRamdhani/ITAM/main/docs/panduan-penggunaan-lengkap.md
A11: AUTH-007 | B11: Fondasi | C11: Auth and Dashboard | D11: Dashboard Visibility | E11: Memastikan launcher mengikuti role user. | F11: Authorization | G11: SUPERADMIN/TENANT_ADMIN/ITAM_MANAGER/AUDITOR | H11: High | I11: Siapkan beberapa akun dengan role berbeda. | J11: 1. Login sebagai role pertama dan catat launcher yang muncul. 2. Logout lalu login sebagai role kedua. 3. Bandingkan launcher dan tombol aksi yang terlihat. | K11: - Launcher mengikuti role. - Modul yang tidak relevan tidak ditampilkan. - Tidak ada tombol aksi write untuk role read-only. | M11: Not Started | P11: https://raw.githubusercontent.com/MuhamadRamdhani/ITAM/main/docs/matriks-akses-role.md
A12: AUTH-008 | B12: Fondasi | C12: Auth and Dashboard | D12: Login | E12: Memastikan login ditolak bila captcha belum diisi atau token captcha invalid/expired. | F12: Negative | G12: Public | H12: High | I12: Tenant aktif; akun aktif; site key captcha tersedia. | J12: 1. Buka halaman login. 2. Isi Tenant Code, Email Address, dan Password valid. 3. Jangan selesaikan captcha atau gunakan token captcha invalid. 4. Klik login. | K12: - Login ditolak. - Pesan captcha tampil. - Widget captcha di-reset bila token invalid/expired. | L12: captcha kosong / captcha invalid | M12: Not Started | P12: https://raw.githubusercontent.com/MuhamadRamdhani/ITAM/main/apps/web/app/login/page.tsx
